Workbook

Sheet README
A1: Project | B1: Purpose | C1: Records | D1: Recommended Tools | E1: Important Note
A2: HR Workforce Analytics and Interactive Dashboard System | B2: Synthetic project-ready HR dataset for Employee Demographics, Recruitment, Attendance, Leave, Salary, Performance, Attrition and Department-wise Dashboard. | C2: 300 employees; 3600 monthly attendance records; 640 leave records | D2: Excel → MySQL → Power BI; Python/Pandas for optional preprocessing | E2: All names and records are synthetic/fictitious and created for academic/project use.

Sheet Employee_Master
A1: Employee_ID | B1: Employee_Name | C1: Gender | D1: Age | E1: Age Group | F1: Department | G1: Position | H1: Salary | I1: Hire_Date | J1: Years_of_Service | K1: Experience Group | L1: Recruitment_Source | M1: Performance_Score | N1: Attendance_Percentage | O1: Absence_Days | P1: Leave_Days | Q1: Employment_Status | R1: Termination_Date | S1: Location
A2: 1 | B2: Employee_001 | C2: Male | D2: 38 | E2: {=_xlfn.IFS(Table1[[#This Row],[Age]]<=30, "18-30",Table1[[#This Row],[Age]]<=40, "31-40", Table1[[#This Row],[Age]]<=50, "41-50", TRUE, "51-65")} -> 31-40 | F2: Marketing | G2: Marketing Executive | H2: 48000 | I2: 44469 | J2: 5 | K2: {=_xlfn.IFS(Table1[[#This Row],[Years_of_Service]]<=2, "0-2 Years", Table1[[#This Row],[Years_of_Service]]<=5, "3-5 Years", Table1[[#This Row],[Years_of_Service]]<=8, "6-8 Years", TRUE, "8 Years")} -> 3-5 Years | L2: Campus Recruitment | M2: 84.1 | N2: 97.6 | O2: 13 | P2: 1 | Q2: Active | S2: North
A3: 2 | B3: Employee_002 | C3: Male | D3: 53 | E3: {=_xlfn.IFS(Table1[[#This Row],[Age]]<=30, "18-30",Table1[[#This Row],[Age]]<=40, "31-40", Table1[[#This Row],[Age]]<=50, "41-50", TRUE, "51-65")} -> 51-65 | F3: IT | G3: Data Analyst | H3: 74000 | I3: 45566 | J3: 1 | K3: {=_xlfn.IFS(Table1[[#This Row],[Years_of_Service]]<=2, "0-2 Years", Table1[[#This Row],[Years_of_Service]]<=5, "3-5 Years", Table1[[#This Row],[Years_of_Service]]<=8, "6-8 Years", TRUE, "8 Years")} -> 0-2 Years | L3: Indeed | M3: 56.1 | N3: 85.5 | O3: 14 | P3: 18 | Q3: Resigned | R3: 45872 | S3: East
A4: 3 | B4: Employee_003 | C4: Male | D4: 48 | E4: {=_xlfn.IFS(Table1[[#This Row],[Age]]<=30, "18-30",Table1[[#This Row],[Age]]<=40, "31-40", Table1[[#This Row],[Age]]<=50, "41-50", TRUE, "51-65")} -> 41-50 | F4: Customer Support | G4: Support Executive | H4: 35000 | I4: 44859 | J4: 4 | K4: {=_xlfn.IFS(Table1[[#This Row],[Years_of_Service]]<=2, "0-2 Years", Table1[[#This Row],[Years_of_Service]]<=5, "3-5 Years", Table1[[#This Row],[Years_of_Service]]<=8, "6-8 Years", TRUE, "8 Years")} -> 3-5 Years | L4: LinkedIn | M4: 87.8 | N4: 83.8 | O4: 11 | P4: 11 | Q4: Active | S4: Central
A5: 4 | B5: Employee_004 | C5: Female | D5: 55 | E5: {=_xlfn.IFS(Table1[[#This Row],[Age]]<=30, "18-30",Table1[[#This Row],[Age]]<=40, "31-40", Table1[[#This Row],[Age]]<=50, "41-50", TRUE, "51-65")} -> 51-65 | F5: HR | G5: HR Executive | H5: 51000 | I5: 43977 | J5: 6.4 | K5: {=_xlfn.IFS(Table1[[#This Row],[Years_of_Service]]<=2, "0-2 Years", Table1[[#This Row],[Years_of_Service]]<=5, "3-5 Years", Table1[[#This Row],[Years_of_Service]]<=8, "6-8 Years", TRUE, "8 Years")} -> 6-8 Years | L5: Naukri | M5: 96.8 | N5: 88.6 | O5: 19 | P5: 11 | Q5: Resigned | R5: 46001 | S5: Central
A6: 5 | B6: Employee_005 | C6: Male | D6: 23 | E6: {=_xlfn.IFS(Table1[[#This Row],[Age]]<=30, "18-30",Table1[[#This Row],[Age]]<=40, "31-40", Table1[[#This Row],[Age]]<=50, "41-50", TRUE, "51-65")} -> 18-30 | F6: Sales | G6: Business Development Executive | H6: 43000 | I6: 46174 | J6: 0.4 | K6: {=_xlfn.IFS(Table1[[#This Row],[Years_of_Service]]<=2, "0-2 Years", Table1[[#This Row],[Years_of_Service]]<=5, "3-5 Years", Table1[[#This Row],[Years_of_Service]]<=8, "6-8 Years", TRUE, "8 Years")} -> 0-2 Years | L6: Company Website | M6: 58.4 | N6: 86.1 | O6: 8 | P6: 14 | Q6: Active | S6: East
A7: 6 | B7: Employee_006 | C7: Female | D7: 34 | E7: {=_xlfn.IFS(Table1[[#This Row],[Age]]<=30, "18-30",Table1[[#This Row],[Age]]<=40, "31-40", Table1[[#This Row],[Age]]<=50, "41-50", TRUE, "51-65")} -> 31-40 | F7: Sales | G7: Sales Manager | H7: 49000 | I7: 46211 | J7: 0.2 | K7: {=_xlfn.IFS(Table1[[#This Row],[Years_of_Service]]<=2, "0-2 Years", Table1[[#This Row],[Years_of_Service]]<=5, "3-5 Years", Table1[[#This Row],[Years_of_Service]]<=8, "6-8 Years", TRUE, "8 Years")} -> 0-2 Years | L7: Campus Recruitment | M7: 66.5 | N7: 98.4 | O7: 20 | P7: 5 | Q7: Active | S7: Central
A8: 7 | B8: Employee_007 | C8: Male | D8: 50 | E8: {=_xlfn.IFS(Table1[[#This Row],[Age]]<=30, "18-30",Table1[[#This Row],[Age]]<=40, "31-40", Table1[[#This Row],[Age]]<=50, "41-50", TRUE, "51-65")} -> 41-50 | F8: Marketing | G8: Marketing Executive | H8: 43000 | I8: 45020 | J8: 3.5 | K8: {=_xlfn.IFS(Table1[[#This Row],[Years_of_Service]]<=2, "0-2 Years", Table1[[#This Row],[Years_of_Service]]<=5, "3-5 Years", Table1[[#This Row],[Years_of_Service]]<=8, "6-8 Years", TRUE, "8 Years")} -> 3-5 Years | L8: LinkedIn | M8: 84.6 | N8: 85.8 | O8: 7 | P8: 1 | Q8: Active | S8: East
A9: 8 | B9: Employee_008 | C9: Male | D9: 34 | E9: {=_xlfn.IFS(Table1[[#This Row],[Age]]<=30, "18-30",Table1[[#This Row],[Age]]<=40, "31-40", Table1[[#This Row],[Age]]<=50, "41-50", TRUE, "51-65")} -> 31-40 | F9: Finance | G9: Financial Analyst | H9: 77000 | I9: 45789 | J9: 1.4 | K9: {=_xlfn.IFS(Table1[[#This Row],[Years_of_Service]]<=2, "0-2 Years", Table1[[#This Row],[Years_of_Service]]<=5, "3-5 Years", Table1[[#This Row],[Years_of_Service]]<=8, "6-8 Years", TRUE, "8 Years")} -> 0-2 Years | L9: Company Website | M9: 92.7 | N9: 87.5 | O9: 20 | P9: 14 | Q9: Active | S9: South
A10: 9 | B10: Employee_009 | C10: Male | D10: 56 | E10: {=_xlfn.IFS(Table1[[#This Row],[Age]]<=30, "18-30",Table1[[#This Row],[Age]]<=40, "31-40", Table1[[#This Row],[Age]]<=50, "41-50", TRUE, "51-65")} -> 51-65 | F10: HR | G10: HR Executive | H10: 43000 | I10: 45673 | J10: 1.7 | K10: {=_xlfn.IFS(Table1[[#This Row],[Years_of_Service]]<=2, "0-2 Years", Table1[[#This Row],[Years_of_Service]]<=5, "3-5 Years", Table1[[#This Row],[Years_of_Service]]<=8, "6-8 Years", TRUE, "8 Years")} -> 0-2 Years | L10: Indeed | M10: 93.6 | N10: 89 | O10: 16 | P10: 15 | Q10: Active | S10: North
A11: 10 | B11: Employee_010 | C11: Male | D11: 30 | E11: {=_xlfn.IFS(Table1[[#This Row],[Age]]<=30, "18-30",Table1[[#This Row],[Age]]<=40, "31-40", Table1[[#This Row],[Age]]<=50, "41-50", TRUE, "51-65")} -> 18-30 | F11: Customer Support | G11: Support Executive | H11: 46000 | I11: 46036 | J11: 0.7 | K11: {=_xlfn.IFS(Table1[[#This Row],[Years_of_Service]]<=2, "0-2 Years", Table1[[#This Row],[Years_of_Service]]<=5, "3-5 Years", Table1[[#This Row],[Years_of_Service]]<=8, "6-8 Years", TRUE, "8 Years")} -> 0-2 Years | L11: Company Website | M11: 61.9 | N11: 93.9 | O11: 12 | P11: 14 | Q11: Resigned | R11: 46236 | S11: Central
A12: 11 | B12: Employee_011 | C12: Male | D12: 28 | E12: {=_xlfn.IFS(Table1[[#This Row],[Age]]<=30, "18-30",Table1[[#This Row],[Age]]<=40, "31-40", Table1[[#This Row],[Age]]<=50, "41-50", TRUE, "51-65")} -> 18-30 | F12: HR | G12: Recruiter | H12: 57000 | I12: 46258 | J12: 0.1 | K12: {=_xlfn.IFS(Table1[[#This Row],[Years_of_Service]]<=2, "0-2 Years", Table1[[#This Row],[Years_of_Service]]<=5, "3-5 Years", Table1[[#This Row],[Years_of_Service]]<=8, "6-8 Years", TRUE, "8 Years")} -> 0-2 Years | L12: Company Website | M12: 88 | N12: 88 | O12: 5 | P12: 14 | Q12: Active | S12: North
A13: 12 | B13: Employee_012 | C13: Female | D13: 53 | E13: {=_xlfn.IFS(Table1[[#This Row],[Age]]<=30, "18-30",Table1[[#This Row],[Age]]<=40, "31-40", Table1[[#This Row],[Age]]<=50, "41-50", TRUE, "51-65")} -> 51-65 | F13: Marketing | G13: Marketing Manager | H13: 34000 | I13: 44197 | J13: 5.8 | K13: {=_xlfn.IFS(Table1[[#This Row],[Years_of_Service]]<=2, "0-2 Years", Table1[[#This Row],[Years_of_Service]]<=5, "3-5 Years", Table1[[#This Row],[Years_of_Service]]<=8, "6-8 Years", TRUE, "8 Years")} -> 6-8 Years | L13: Naukri | M13: 76.8 | N13: 83.9 | O13: 16 | P13: 6 | Q13: Active | S13: South
A14: 13 | B14: Employee_013 | C14: Male | D14: 41 | E14: {=_xlfn.IFS(Table1[[#This Row],[Age]]<=30, "18-30",Table1[[#This Row],[Age]]<=40, "31-40", Table1[[#This Row],[Age]]<=50, "41-50", TRUE, "51-65")} -> 41-50 | F14: HR | G14: HR Executive | H14: 67000 | I14: 45467 | J14: 2.3 | K14: {=_xlfn.IFS(Table1[[#This Row],[Years_of_Service]]<=2, "0-2 Years", Table1[[#This Row],[Years_of_Service]]<=5, "3-5 Years", Table1[[#This Row],[Years_of_Service]]<=8, "6-8 Years", TRUE, "8 Years")} -> 3-5 Years | L14: Indeed | M14: 92.8 | N14: 96.6 | O14: 1 | P14: 7 | Q14: Active | S14: Central
A15: 14 | B15: Employee_014 | C15: Female | D15: 25 | E15: {=_xlfn.IFS(Table1[[#This Row],[Age]]<=30, "18-30",Table1[[#This Row],[Age]]<=40, "31-40", Table1[[#This Row],[Age]]<=50, "41-50", TRUE, "51-65")} -> 18-30 | F15: IT | G15: Software Developer | H15: 58000 | I15: 45647 | J15: 1.8 | K15: {=_xlfn.IFS(Table1[[#This Row],[Years_of_Service]]<=2, "0-2 Years", Table1[[#This Row],[Years_of_Service]]<=5, "3-5 Years", Table1[[#This Row],[Years_of_Service]]<=8, "6-8 Years", TRUE, "8 Years")} -> 0-2 Years | L15: Campus Recruitment | M15: 87.9 | N15: 84.2 | O15: 5 | P15: 8 | Q15: Active | S15: Central
A16: 15 | B16: Employee_015 | C16: Female | D16: 34 | E16: {=_xlfn.IFS(Table1[[#This Row],[Age]]<=30, "18-30",Table1[[#This Row],[Age]]<=40, "31-40", Table1[[#This Row],[Age]]<=50, "41-50", TRUE, "51-65")} -> 31-40 | F16: Customer Support | G16: Customer Success Executive | H16: 36000 | I16: 45674 | J16: 1.7 | K16: {=_xlfn.IFS(Table1[[#This Row],[Years_of_Service]]<=2, "0-2 Years", Table1[[#This Row],[Years_of_Service]]<=5, "3-5 Years", Table1[[#This Row],[Years_of_Service]]<=8, "6-8 Years", TRUE, "8 Years")} -> 0-2 Years | L16: Company Website | M16: 85.7 | N16: 89 | O16: 16 | P16: 14 | Q16: Active | S16: North
A17: 16 | B17: Employee_016 | C17: Male | D17: 42 | E17: {=_xlfn.IFS(Table1[[#This Row],[Age]]<=30, "18-30",Table1[[#This Row],[Age]]<=40, "31-40", Table1[[#This Row],[Age]]<=50, "41-50", TRUE, "51-65")} -> 41-50 | F17: Sales | G17: Sales Executive | H17: 27000 | I17: 43552 | J17: 7.5 | K17: {=_xlfn.IFS(Table1[[#This Row],[Years_of_Service]]<=2, "0-2 Years", Table1[[#This Row],[Years_of_Service]]<=5, "3-5 Years", Table1[[#This Row],[Years_of_Service]]<=8, "6-8 Years", TRUE, "8 Years")} -> 6-8 Years | L17: LinkedIn | M17: 80.3 | N17: 86 | O17: 2 | P17: 1 | Q17: Active | S17: South
A18: 17 | B18: Employee_017 | C18: Female | D18: 25 | E18: {=_xlfn.IFS(Table1[[#This Row],[Age]]<=30, "18-30",Table1[[#This Row],[Age]]<=40, "31-40", Table1[[#This Row],[Age]]<=50, "41-50", TRUE, "51-65")} -> 18-30 | F18: IT | G18: Software Developer | H18: 56000 | I18: 45571 | J18: 2 | K18: {=_xlfn.IFS(Table1[[#This Row],[Years_of_Service]]<=2, "0-2 Years", Table1[[#This Row],[Years_of_Service]]<=5, "3-5 Years", Table1[[#This Row],[Years_of_Service]]<=8, "6-8 Years", TRUE, "8 Years")} -> 0-2 Years | L18: Company Website | M18: 64.2 | N18: 84.3 | O18: 7 | P18: 15 | Q18: Resigned | R18: 45711 | S18: West
A19: 18 | B19: Employee_018 | C19: Male | D19: 48 | E19: {=_xlfn.IFS(Table1[[#This Row],[Age]]<=30, "18-30",Table1[[#This Row],[Age]]<=40, "31-40", Table1[[#This Row],[Age]]<=50, "41-50", TRUE, "51-65")} -> 41-50 | F19: Sales | G19: Sales Executive | H19: 55000 | I19: 44917 | J19: 3.8 | K19: {=_xlfn.IFS(Table1[[#This Row],[Years_of_Service]]<=2, "0-2 Years", Table1[[#This Row],[Years_of_Service]]<=5, "3-5 Years", Table1[[#This Row],[Years_of_Service]]<=8, "6-8 Years", TRUE, "8 Years")} -> 3-5 Years | L19: Naukri | M19: 73.2 | N19: 90.2 | O19: 20 | P19: 3 | Q19: Active | S19: North
A20: 19 | B20: Employee_019 | C20: Female | D20: 27 | E20: {=_xlfn.IFS(Table1[[#This Row],[Age]]<=30, "18-30",Table1[[#This Row],[Age]]<=40, "31-40", Table1[[#This Row],[Age]]<=50, "41-50", TRUE, "51-65")} -> 18-30 | F20: Finance | G20: Finance Manager | H20: 57000 | I20: 44484 | J20: 5 | K20: {=_xlfn.IFS(Table1[[#This Row],[Years_of_Service]]<=2, "0-2 Years", Table1[[#This Row],[Years_of_Service]]<=5, "3-5 Years", Table1[[#This Row],[Years_of_Service]]<=8, "6-8 Years", TRUE, "8 Years")} -> 3-5 Years | L20: Indeed | M20: 61 | N20: 85.2 | O20: 2 | P20: 14 | Q20: Active | S20: Central
A21: 20 | B21: Employee_020 | C21: Male | D21: 26 | E21: {=_xlfn.IFS(Table1[[#This Row],[Age]]<=30, "18-30",Table1[[#This Row],[Age]]<=40, "31-40", Table1[[#This Row],[Age]]<=50, "41-50", TRUE, "51-65")} -> 18-30 | F21: IT | G21: Software Developer | H21: 69000 | I21: 44434 | J21: 5.1 | K21: {=_xlfn.IFS(Table1[[#This Row],[Years_of_Service]]<=2, "0-2 Years", Table1[[#This Row],[Years_of_Service]]<=5, "3-5 Years", Table1[[#This Row],[Years_of_Service]]<=8, "6-8 Years", TRUE, "8 Years")} -> 6-8 Years | L21: Company Website | M21: 62.2 | N21: 90.5 | O21: 1 | P21: 5 | Q21: Active | S21: West
A22: 21 | B22: Employee_021 | C22: Female | D22: 50 | E22: {=_xlfn.IFS(Table1[[#This Row],[Age]]<=30, "18-30",Table1[[#This Row],[Age]]<=40, "31-40", Table1[[#This Row],[Age]]<=50, "41-50", TRUE, "51-65")} -> 41-50 | F22: IT | G22: QA Engineer | H22: 28000 | I22: 44634 | J22: 4.6 | K22: {=_xlfn.IFS(Table1[[#This Row],[Years_of_Service]]<=2, "0-2 Years", Table1[[#This Row],[Years_of_Service]]<=5, "3-5 Years", Table1[[#This Row],[Years_of_Service]]<=8, "6-8 Years", TRUE, "8 Years")} -> 3-5 Years | L22: Indeed | M22: 97.8 | N22: 91.7 | O22: 6 | P22: 9 | Q22: Active | S22: South
A23: 22 | B23: Employee_022 | C23: Female | D23: 24 | E23: {=_xlfn.IFS(Table1[[#This Row],[Age]]<=30, "18-30",Table1[[#This Row],[Age]]<=40, "31-40", Table1[[#This Row],[Age]]<=50, "41-50", TRUE, "51-65")} -> 18-30 | F23: IT | G23: Software Developer | H23: 69000 | I23: 43671 | J23: 7.2 | K23: {=_xlfn.IFS(Table1[[#This Row],[Years_of_Service]]<=2, "0-2 Years", Table1[[#This Row],[Years_of_Service]]<=5, "3-5 Years", Table1[[#This Row],[Years_of_Service]]<=8, "6-8 Years", TRUE, "8 Years")} -> 6-8 Years | L23: LinkedIn | M23: 80.1 | N23: 90.8 | O23: 16 | P23: 2 | Q23: Resigned | R23: 46140 | S23: South
A24: 23 | B24: Employee_023 | C24: Male | D24: 46 | E24: {=_xlfn.IFS(Table1[[#This Row],[Age]]<=30, "18-30",Table1[[#This Row],[Age]]<=40, "31-40", Table1[[#This Row],[Age]]<=50, "41-50", TRUE, "51-65")} -> 41-50 | F24: IT | G24: Software Developer | H24: 69000 | I24: 43957 | J24: 6.4 | K24: {=_xlfn.IFS(Table1[[#This Row],[Years_of_Service]]<=2, "0-2 Years", Table1[[#This Row],[Years_of_Service]]<=5, "3-5 Years", Table1[[#This Row],[Years_of_Service]]<=8, "6-8 Years", TRUE, "8 Years")} -> 6-8 Years | L24: Company Website | M24: 79.9 | N24: 82.7 | O24: 21 | P24: 18 | Q24: Active | S24: Central
A25: 24 | B25: Employee_024 | C25: Female | D25: 34 | E25: {=_xlfn.IFS(Table1[[#This Row],[Age]]<=30, "18-30",Table1[[#This Row],[Age]]<=40, "31-40", Table1[[#This Row],[Age]]<=50, "41-50", TRUE, "51-65")} -> 31-40 | F25: Operations | G25: Operations Manager | H25: 38000 | I25: 46209 | J25: 0.3 | K25: {=_xlfn.IFS(Table1[[#This Row],[Years_of_Service]]<=2, "0-2 Years", Table1[[#This Row],[Years_of_Service]]<=5, "3-5 Years", Table1[[#This Row],[Years_of_Service]]<=8, "6-8 Years", TRUE, "8 Years")} -> 0-2 Years | L25: Indeed | M25: 85.8 | N25: 86.2 | O25: 21 | P25: 9 | Q25: Active | S25: West
A26: 25 | B26: Employee_025 | C26: Male | D26: 50 | E26: {=_xlfn.IFS(Table1[[#This Row],[Age]]<=30, "18-30",Table1[[#This Row],[Age]]<=40, "31-40", Table1[[#This Row],[Age]]<=50, "41-50", TRUE, "51-65")} -> 41-50 | F26: HR | G26: HR Executive | H26: 77000 | I26: 46010 | J26: 0.8 | K26: {=_xlfn.IFS(Table1[[#This Row],[Years_of_Service]]<=2, "0-2 Years", Table1[[#This Row],[Years_of_Service]]<=5, "3-5 Years", Table1[[#This Row],[Years_of_Service]]<=8, "6-8 Years", TRUE, "8 Years")} -> 0-2 Years | L26: Indeed | M26: 58.2 | N26: 85.7 | O26: 11 | P26: 2 | Q26: Active | S26: South
A27: 26 | B27: Employee_026 | C27: Male | D27: 49 | E27: {=_xlfn.IFS(Table1[[#This Row],[Age]]<=30, "18-30",Table1[[#This Row],[Age]]<=40, "31-40", Table1[[#This Row],[Age]]<=50, "41-50", TRUE, "51-65")} -> 41-50 | F27: HR | G27: HR Manager | H27: 44000 | I27: 45691 | J27: 1.7 | K27: {=_xlfn.IFS(Table1[[#This Row],[Years_of_Service]]<=2, "0-2 Years", Table1[[#This Row],[Years_of_Service]]<=5, "3-5 Years", Table1[[#This Row],[Years_of_Service]]<=8, "6-8 Years", TRUE, "8 Years")} -> 0-2 Years | L27: Naukri | M27: 85.3 | N27: 92.7 | O27: 17 | P27: 9 | Q27: Resigned | R27: 46293 | S27: North
A28: 27 | B28: Employee_027 | C28: Male | D28: 27 | E28: {=_xlfn.IFS(Table1[[#This Row],[Age]]<=30, "18-30",Table1[[#This Row],[Age]]<=40, "31-40", Table1[[#This Row],[Age]]<=50, "41-50", TRUE, "51-65")} -> 18-30 | F28: Sales | G28: Sales Manager | H28: 46000 | I28: 45732 | J28: 1.6 | K28: {=_xlfn.IFS(Table1[[#This Row],[Years_of_Service]]<=2, "0-2 Years", Table1[[#This Row],[Years_of_Service]]<=5, "3-5 Years", Table1[[#This Row],[Years_of_Service]]<=8, "6-8 Years", TRUE, "8 Years")} -> 0-2 Years | L28: Campus Recruitment | M28: 64.1 | N28: 88 | O28: 15 | P28: 8 | Q28: Active | S28: North
A29: 28 | B29: Employee_028 | C29: Female | D29: 23 | E29: {=_xlfn.IFS(Table1[[#This Row],[Age]]<=30, "18-30",Table1[[#This Row],[Age]]<=40, "31-40", Table1[[#This Row],[Age]]<=50, "41-50", TRUE, "51-65")} -> 18-30 | F29: IT | G29: QA Engineer | H29: 63000 | I29: 43480 | J29: 7.7 | K29: {=_xlfn.IFS(Table1[[#This Row],[Years_of_Service]]<=2, "0-2 Years", Table1[[#This Row],[Years_of_Service]]<=5, "3-5 Years", Table1[[#This Row],[Years_of_Service]]<=8, "6-8 Years", TRUE, "8 Years")} -> 6-8 Years | L29: Indeed | M29: 69.3 | N29: 84.3 | O29: 23 | P29: 14 | Q29: Active | S29: Central
A30: 29 | B30: Employee_029 | C30: Male | D30: 28 | E30: {=_xlfn.IFS(Table1[[#This Row],[Age]]<=30, "18-30",Table1[[#This Row],[Age]]<=40, "31-40", Table1[[#This Row],[Age]]<=50, "41-50", TRUE, "51-65")} -> 18-30 | F30: Marketing | G30: Digital Marketing Analyst | H30: 60000 | I30: 43774 | J30: 6.9 | K30: {=_xlfn.IFS(Table1[[#This Row],[Years_of_Service]]<=2, "0-2 Years", Table1[[#This Row],[Years_of_Service]]<=5, "3-5 Years", Table1[[#This Row],[Years_of_Service]]<=8, "6-8 Years", TRUE, "8 Years")} -> 6-8 Years | L30: Campus Recruitment | M30: 61.4 | N30: 82.6 | O30: 17 | P30: 4 | Q30: Active | S30: West
A31: 30 | B31: Employee_030 | C31: Female | D31: 44 | E31: {=_xlfn.IFS(Table1[[#This Row],[Age]]<=30, "18-30",Table1[[#This Row],[Age]]<=40, "31-40", Table1[[#This Row],[Age]]<=50, "41-50", TRUE, "51-65")} -> 41-50 | F31: Sales | G31: Sales Executive | H31: 37000 | I31: 43629 | J31: 7.3 | K31: {=_xlfn.IFS(Table1[[#This Row],[Years_of_Service]]<=2, "0-2 Years", Table1[[#This Row],[Years_of_Service]]<=5, "3-5 Years", Table1[[#This Row],[Years_of_Service]]<=8, "6-8 Years", TRUE, "8 Years")} -> 6-8 Years | L31: Naukri | M31: 93.7 | N31: 85.7 | O31: 3 | P31: 11 | Q31: Active | S31: Central
A32: 31 | B32: Employee_031 | C32: Male | D32: 36 | E32: {=_xlfn.IFS(Table1[[#This Row],[Age]]<=30, "18-30",Table1[[#This Row],[Age]]<=40, "31-40", Table1[[#This Row],[Age]]<=50, "41-50", TRUE, "51-65")} -> 31-40 | F32: Customer Support | G32: Support Lead | H32: 50000 | I32: 44131 | J32: 5.9 | K32: {=_xlfn.IFS(Table1[[#This Row],[Years_of_Service]]<=2, "0-2 Years", Table1[[#This Row],[Years_of_Service]]<=5, "3-5 Years", Table1[[#This Row],[Years_of_Service]]<=8, "6-8 Years", TRUE, "8 Years")} -> 6-8 Years | L32: Company Website | M32: 92.9 | N32: 82.4 | O32: 21 | P32: 7 | Q32: Active | S32: East
A33: 32 | B33: Employee_032 | C33: Male | D33: 45 | E33: {=_xlfn.IFS(Table1[[#This Row],[Age]]<=30, "18-30",Table1[[#This Row],[Age]]<=40, "31-40", Table1[[#This Row],[Age]]<=50, "41-50", TRUE, "51-65")} -> 41-50 | F33: Sales | G33: Business Development Executive | H33: 39000 | I33: 43624 | J33: 7.3 | K33: {=_xlfn.IFS(Table1[[#This Row],[Years_of_Service]]<=2, "0-2 Years", Table1[[#This Row],[Years_of_Service]]<=5, "3-5 Years", Table1[[#This Row],[Years_of_Service]]<=8, "6-8 Years", TRUE, "8 Years")} -> 6-8 Years | L33: Employee Referral | M33: 91.9 | N33: 85.9 | O33: 9 | P33: 7 | Q33: Active | S33: South
A34: 33 | B34: Employee_033 | C34: Female | D34: 42 | E34: {=_xlfn.IFS(Table1[[#This Row],[Age]]<=30, "18-30",Table1[[#This Row],[Age]]<=40, "31-40", Table1[[#This Row],[Age]]<=50, "41-50", TRUE, "51-65")} -> 41-50 | F34: IT | G34: Data Analyst | H34: 75000 | I34: 44607 | J34: 4.6 | K34: {=_xlfn.IFS(Table1[[#This Row],[Years_of_Service]]<=2, "0-2 Years", Table1[[#This Row],[Years_of_Service]]<=5, "3-5 Years", Table1[[#This Row],[Years_of_Service]]<=8, "6-8 Years", TRUE, "8 Years")} -> 3-5 Years | L34: Naukri | M34: 67 | N34: 93.2 | O34: 17 | P34: 10 | Q34: Active | S34: North
A35: 34 | B35: Employee_034 | C35: Male | D35: 58 | E35: {=_xlfn.IFS(Table1[[#This Row],[Age]]<=30, "18-30",Table1[[#This Row],[Age]]<=40, "31-40", Table1[[#This Row],[Age]]<=50, "41-50", TRUE, "51-65")} -> 51-65 | F35: IT | G35: System Administrator | H35: 31000 | I35: 44553 | J35: 4.8 | K35: {=_xlfn.IFS(Table1[[#This Row],[Years_of_Service]]<=2, "0-2 Years", Table1[[#This Row],[Years_of_Service]]<=5, "3-5 Years", Table1[[#This Row],[Years_of_Service]]<=8, "6-8 Years", TRUE, "8 Years")} -> 3-5 Years | L35: Naukri | M35: 56.6 | N35: 92.4 | O35: 10 | P35: 13 | Q35: Active | S35: Central
A36: 35 | B36: Employee_035 | C36: Female | D36: 57 | E36: {=_xlfn.IFS(Table1[[#This Row],[Age]]<=30, "18-30",Table1[[#This Row],[Age]]<=40, "31-40", Table1[[#This Row],[Age]]<=50, "41-50", TRUE, "51-65")} -> 51-65 | F36: Operations | G36: Operations Executive | H36: 42000 | I36: 44244 | J36: 5.6 | K36: {=_xlfn.IFS(Table1[[#This Row],[Years_of_Service]]<=2, "0-2 Years", Table1[[#This Row],[Years_of_Service]]<=5, "3-5 Years", Table1[[#This Row],[Years_of_Service]]<=8, "6-8 Years", TRUE, "8 Years")} -> 6-8 Years | L36: Indeed | M36: 55.1 | N36: 98.2 | O36: 11 | P36: 13 | Q36: Resigned | R36: 45615 | S36: North
A37: 36 | B37: Employee_036 | C37: Female | D37: 28 | E37: {=_xlfn.IFS(Table1[[#This Row],[Age]]<=30, "18-30",Table1[[#This Row],[Age]]<=40, "31-40", Table1[[#This Row],[Age]]<=50, "41-50", TRUE, "51-65")} -> 18-30 | F37: Marketing | G37: Digital Marketing Analyst | H37: 61000 | I37: 44696 | J37: 4.4 | K37: {=_xlfn.IFS(Table1[[#This Row],[Years_of_Service]]<=2, "0-2 Years", Table1[[#This Row],[Years_of_Service]]<=5, "3-5 Years", Table1[[#This Row],[Years_of_Service]]<=8, "6-8 Years", TRUE, "8 Years")} -> 3-5 Years | L37: Company Website | M37: 76.8 | N37: 93.7 | O37: 22 | P37: 9 | Q37: Active | S37: Central
A38: 37 | B38: Employee_037 | C38: Female | D38: 45 | E38: {=_xlfn.IFS(Table1[[#This Row],[Age]]<=30, "18-30",Table1[[#This Row],[Age]]<=40, "31-40", Table1[[#This Row],[Age]]<=50, "41-50", TRUE, "51-65")} -> 41-50 | F38: Sales | G38: Sales Executive | H38: 41000 | I38: 46240 | J38: 0.2 | K38: {=_xlfn.IFS(Table1[[#This Row],[Years_of_Service]]<=2, "0-2 Years", Table1[[#This Row],[Years_of_Service]]<=5, "3-5 Years", Table1[[#This Row],[Years_of_Service]]<=8, "6-8 Years", TRUE, "8 Years")} -> 0-2 Years | L38: Employee Referral | M38: 79.5 | N38: 89.1 | O38: 9 | P38: 6 | Q38: Active | S38: West
A39: 38 | B39: Employee_038 | C39: Female | D39: 50 | E39: {=_xlfn.IFS(Table1[[#This Row],[Age]]<=30, "18-30",Table1[[#This Row],[Age]]<=40, "31-40", Table1[[#This Row],[Age]]<=50, "41-50", TRUE, "51-65")} -> 41-50 | F39: Customer Support | G39: Customer Success Executive | H39: 31000 | I39: 45275 | J39: 2.8 | K39: {=_xlfn.IFS(Table1[[#This Row],[Years_of_Service]]<=2, "0-2 Years", Table1[[#This Row],[Years_of_Service]]<=5, "3-5 Years", Table1[[#This Row],[Years_of_Service]]<=8, "6-8 Years", TRUE, "8 Years")} -> 3-5 Years | L39: Naukri | M39: 74 | N39: 85.7 | O39: 5 | P39: 2 | Q39: Active | S39: East
A40: 39 | B40: Employee_039 | C40: Female | D40: 26 | E40: {=_xlfn.IFS(Table1[[#This Row],[Age]]<=30, "18-30",Table1[[#This Row],[Age]]<=40, "31-40", Table1[[#This Row],[Age]]<=50, "41-50", TRUE, "51-65")} -> 18-30 | F40: Operations | G40: Process Analyst | H40: 39000 | I40: 44428 | J40: 5.1 | K40: {=_xlfn.IFS(Table1[[#This Row],[Years_of_Service]]<=2, "0-2 Years", Table1[[#This Row],[Years_of_Service]]<=5, "3-5 Years", Table1[[#This Row],[Years_of_Service]]<=8, "6-8 Years", TRUE, "8 Years")} -> 6-8 Years | L40: Company Website | M40: 63.6 | N40: 82.4 | O40: 19 | P40: 2 | Q40: Active | S40: West
...

Sheet Demographic Summary
A1: Total Employees | B1: Average Age | C1: Youngest Employees | D1: Oldest Employees | E1: Average Experience | F1: Active Employees | G1: Resigned Employees | H1: % of Total Active
A2: =COUNTA(Employee_Master!A2:A301) -> 300 | B2: =AVERAGE(Employee_Master!D2:D301) -> 40.123333 | C2: =MIN(Employee_Master!D2:D301) -> 21 | D2: =MAX(Employee_Master!D2:D301) -> 58 | E2: =AVERAGE(Employee_Master!J2:J301) -> 3.785 | F2: =COUNTIF(Employee_Master!Q2:Q301, "Active") -> 252 | G2: =COUNTIF(Employee_Master!Q2:Q301, "Resigned") -> 48 | H2: 0.84

Sheet Gender Analysis
A3: Row Labels | B3: Gender % of Total
A4: Female | B4: 0.46
A5: Male | B5: 0.54
A6: Grand Total | B6: 1

Sheet Age Group Distribution
A3: Row Labels | B3: Count of Employee_ID
A4: 18-30 | B4: 82
A5: 31-40 | B5: 67
A6: 41-50 | B6: 89
A7: 51-65 | B7: 62
A8: Grand Total | B8: 300

Sheet Department Headcount
A3: Row Labels | B3: Count of Employee_ID | C3: Average of Years_of_Service
A4: IT | B4: 54 | C4: 3.7018519
A5: Sales | B5: 48 | C5: 3.9479167
A6: HR | B6: 44 | C6: 3.7886364
A7: Finance | B7: 43 | C7: 3.6348837
A8: Customer Support | B8: 40 | C8: 3.58
A9: Marketing | B9: 38 | C9: 4.1210526
A10: Operations | B10: 33 | C10: 3.7363636
A11: Grand Total | B11: 300 | C11: 3.785

Sheet Location-Wise Headcount 
A3: Row Labels | B3: Count of Employee_ID
A4: Central | B4: 60
A5: East | B5: 62
A6: North | B6: 63
A7: South | B7: 56
A8: West | B8: 59
A9: Grand Total | B9: 300

Sheet Position-wise Distribution
A3: Row Labels | B3: Count of Employee_ID
A4: Accountant | B4: 15
A5: Business Development Executive | B5: 16
A6: Customer Success Executive | B6: 14
A7: Data Analyst | B7: 15
A8: Digital Marketing Analyst | B8: 16
A9: Finance Manager | B9: 14
A10: Financial Analyst | B10: 14
A11: HR Executive | B11: 16
A12: HR Manager | B12: 16
A13: Marketing Executive | B13: 13
A14: Marketing Manager | B14: 9
A15: Operations Executive | B15: 12
... A26: Grand Total | B26: 300

Sheet Department vs Gender
A3: Count of Employee_ID | B3: Column Labels
A4: Row Labels | B4: Female | C4: Male | D4: Grand Total
A5: Customer Support | B5: 19 | C5: 21 | D5: 40
A6: Finance | B6: 25 | C6: 18 | D6: 43
A7: HR | B7: 15 | C7: 29 | D7: 44
A8: IT | B8: 24 | C8: 30 | D8: 54
A9: Marketing | B9: 17 | C9: 21 | D9: 38
A10: Operations | B10: 16 | C10: 17 | D10: 33
A11: Sales | B11: 22 | C11: 26 | D11: 48
A12: Grand Total | B12: 138 | C12: 162 | D12: 300

Sheet Active and Resigned
A3: Row Labels | B3: % of Grand Total
A4: Active | B4: 0.84
A5: Resigned | B5: 0.16
A6: Grand Total | B6: 1

Sheet Dashboard
A1: Employee Demographics
